{"context": "test_error_track", "stage": "test", "run_id": "test_run_id", "metadata": {}, "timestamp": "2018-09-07 12:07:33.141023", "exception": {"type": "ValueError", "value": "hello", "traceback": "  File \"tests/test_error.py\", line 32, in test_error_raw_output\n    raise ValueError('hello')\n"}, "id": "fake1"}
{"context": "test_another_track", "stage": "test", "run_id": "test_run_id", "metadata": {}, "timestamp": "2018-09-08 12:07:33.141023", "exception": {"type": "ValueError", "value": "hello", "traceback": "  File \"tests/test_error.py\", line 32, in test_error_raw_output\n    raise ValueError('hello')\n"}, "id": "fake2"}